<?xml version="1.0"?>
<robot
  name="Hamr">

  <material name="Black">
    <color rgba="0.0 0.0 0.0 1.0"/>
  </material>
  <material name="Blue">
    <color rgba="0.0 0.5 0.8 1.0"/>
  </material>
  <material name="Green">
    <color rgba="0.4 1 0.2 1.0"/>
  </material>
  <material name="Grey">
    <color rgba="0.4 0.4 0.4 1.0"/>
  </material>
  <material name="Orange">
    <color rgba="1.0 0.423529411765 0.0392156862745 1.0"/>
  </material>
  <material name="Brown">
    <color rgba="0.870588235294 0.811764705882 0.764705882353 1.0"/>
  </material>
  <material name="Red">
    <color rgba="0.8 0.0 0.0 1.0"/>
  </material>
  <material name="White">
    <color rgba="1.0 1.0 1.0 1.0"/>
  </material>
  <material name="Purple">
    <color rgba="0.7 0.4 0.95 1.0"/>
  </material>

  <link name="Chassis">
    <inertial>
      <origin xyz="0 0 -0.379657560961688" rpy="0 0 0" />
      <mass value=" 1.2066" />
      <inertia ixx="49.0722" ixy="8.7197e-04" ixz="0.2372" iyy="68.1039" iyz="-0.0032" izz="99.7537" />
    </inertial>
    <visual>
      <origin xyz="0 0 0" rpy="0 0 0" />
      <geometry>
        <!-- <mesh filename="meshes/Chassis_new.obj" scale="1000" /> -->
      </geometry>
      <material name="Grey"/>               
    </visual>
  </link>

  <!--- FRONT LEFT SWING || FRONT LEFT SWING || FRONT LEFT SWING --> 
  <!--- FRONT LEFT SWING || FRONT LEFT SWING || FRONT LEFT SWING --> 
  <!--- FRONT LEFT SWING || FRONT LEFT SWING || FRONT LEFT SWING --> 

  <link
    name="FLS1">
    <inertial>
      <origin xyz="0 0 0" rpy="0 0 0" />
      <mass value="8.9854E-04" />
      <inertia ixx="4.0531E-4" ixy="0" ixz="0" iyy="1.8583E-4"  iyz="-1.1771E-5" izz="2.281E-4" />
    </inertial>
    <visual>
      <origin xyz="0 0 0" rpy="0 0 0" />
      <geometry>
        <!-- <mesh filename="meshes/FLS1_new.obj" scale="1000" /> -->
      </geometry>
      <material name="Purple"/>        
    </visual>
  </link>

  <link name="FLS2">
    <inertial>
      <origin xyz="0 3.8176 1.3953" rpy="0 0 0" />
      <mass value="7.2648E-03" />
      <inertia ixx="3.894E-2" ixy="0" ixz="0" iyy="8.899E-3" iyz="-9.1382E-3" izz="3.0111E-2" />
    </inertial>
    <visual>
      <origin xyz="0 0 0" rpy="0 0 0" />
      <geometry>
        <!-- <mesh filename="meshes/FLS2_new.obj" scale="1000" /> -->
      </geometry>
      <material name="Purple"/>        
    </visual>
  </link>

  <link name="FLS3">
    <inertial>
      <origin xyz="0.70289 -8.6332E-02 0.10242" rpy="0 0 0" />
      <mass value="3.889E-03" />
      <inertia ixx="2.6158E-3" ixy="-5.7753E-4" ixz="-3.2642E-4" iyy="4.7809E-3" iyz="-8.2188E-5" izz="3.1897E-3" />
    </inertial>
    <visual>
      <origin xyz="0 0 0" rpy="0 0 0" />
      <geometry>
        <!-- <mesh filename="meshes/FLS3_new.obj" scale="1000" /> -->
      </geometry>
      <material name="Orange"/>       
    </visual>
  </link>

  <link name="FLS4">
    <inertial>
      <origin xyz="1.4605 1.8371 3.0882" rpy="0 0 0" />
      <mass value="1.4269E-02" />
      <inertia ixx="1.206E-1" ixy="3.2785E-2" ixz="-2.9892E-2" iyy="8.3598E-2" iyz="2.1738E-2" izz="9.8829E-2" />
    </inertial>
    <visual>
      <origin xyz="0 0 0" rpy="0 0 0" />
      <geometry>
        <!-- <mesh filename="meshes/FLS4_new.obj" scale="1000" /> -->
      </geometry>
      <material name="Orange"/>        
    </visual>
  </link>

  <!--- FRONT LEFT LIFT || FRONT LEFT LIFT || FRONT LEFT LIFT --> 
  <!--- FRONT LEFT LIFT || FRONT LEFT LIFT || FRONT LEFT LIFT --> 
  <!--- FRONT LEFT LIFT || FRONT LEFT LIFT || FRONT LEFT LIFT --> 

  <link name="FLL1">
    <inertial>
      <origin xyz="-0.2102 2.5512 -5.7375E-02" rpy="0 0 0" />
      <mass value="4.5174E-03" />
      <inertia ixx="1.0604E-2" ixy="9.467E-4" ixz="4.1692E-4" iyy="2.5227E-3" iyz="-2.6756E-4" izz="1.0642E-2" />
    </inertial>
    <visual>
      <origin xyz="0 0 0" rpy="0 0 0" />
      <geometry>
        <!-- <mesh filename="meshes/FLL1_new.obj" scale="1000" /> -->
      </geometry>
      <material name="Blue"/>        
    </visual>
  </link>

  <link name="FLL2">
    <inertial>
      <origin xyz="0 0.95907 0" rpy="0 0 0" />
      <mass value="1.6211E-03" />
      <inertia ixx="9.976E-4" ixy="0" ixz="0" iyy="2.561E-3" iyz="0" izz="3.5431E-3" />
    </inertial>
    <visual>
      <origin xyz="0 0 0" rpy="0 0 0" />
      <geometry>
        <!-- <mesh filename="meshes/FLL2_new.obj" scale="1000" /> -->
      </geometry>
      <material name="Blue"/>        
    </visual>/
  </link>
  
  <link name="FLL3">
    <inertial>
      <origin xyz="0.11652 -7.2167E-02 -0.5651" rpy="0 0 0" />
      <mass value="4.2308E-03" />
      <inertia ixx="2.4566E-3" ixy="-9.4738E-5" ixz="3.1854E-4" iyy="5.8098E-3" iyz="4.7676E-4" izz="4.4079E-3" />
    </inertial>
    <visual>
      <origin xyz="0 0 0" rpy="0 0 0" />
      <geometry>
        <!-- <mesh filename="meshes/FLL3_new.obj" scale="1000" /> -->
      </geometry>
      <material name="Orange"/>        
    </visual>
  </link>

  <link name="FLL4">
    <inertial>
      <origin xyz="-1.0887 3.2212 -3.5924" rpy="0 0 0" />
      <mass value="3.0948E-02" />
      <inertia ixx="0.453879" ixy="0.072379" ixz="-0.038860" iyy="0.325606" iyz="-0.144657" izz="3.4257E-1" />
    </inertial>
    <visual>
      <origin xyz="0 0 0" rpy="0 0 0" />
      <geometry>
        <!-- <mesh filename="meshes/FLL4_new.obj" scale="1000"/> -->
      </geometry>
      <material name="Orange"/>        
    </visual>
    <collision>
      <origin xyz="0 7.58 -11.35" rpy="0 0 0"/>
      <geometry>
        <sphere radius="0" />
      </geometry>
    </collision>
  </link>

  <!--- REAR LEFT SWING || REAR LEFT SWING || REAR LEFT SWING --> 
  <!--- REAR LEFT SWING || REAR LEFT SWING || REAR LEFT SWING --> 
  <!--- REAR LEFT SWING || REAR LEFT SWING || REAR LEFT SWING --> 

  <link name="RLS1">
    <inertial>
      <origin xyz="0 0 0" rpy="0 0 0" />
      <mass  value="8.9854E-04" />
      <inertia ixx="4.0531E-4" ixy="0" ixz="0" iyy="1.8583E-4" iyz="-1.1771E-5" izz="2.281E-4" />
    </inertial>
    <visual>
      <origin xyz="0 0 0" rpy="0 0 0" />
      <geometry>
        <!-- <mesh filename="meshes/RLS1_new.obj" scale="1000" /> -->
      </geometry>
      <material name="Purple"/>   
    </visual>
  </link>
  
  <link name="RLS2">
    <inertial>
      <origin xyz="0 3.8176 1.3953" rpy="0 0 0" />
      <mass value="7.2648E-03" />
      <inertia ixx="3.894E-2" ixy="0" ixz="0" iyy="8.899E-3" iyz="-9.1382E-3" izz="3.0111E-2" />
    </inertial>
    <visual>
      <origin xyz="0 0 0" rpy="0 0 0" />
      <geometry>
        <!-- <mesh filename="meshes/RLS2_new.obj" scale="1000" /> -->
      </geometry>
      <material name="Purple"/>
    </visual>
  </link>
  
  <link name="RLS3">
    <inertial>
      <origin xyz="-0.70289 -8.6332E-02 0.10242" rpy="0 0 0" />
      <mass value="3.889E-03" />
      <inertia ixx="2.6158E-3" ixy="5.7753E-4" ixz="3.2642E-4" iyy="4.7809E-3" iyz="-8.2188E-5" izz="3.1897E-3" />
    </inertial>
    <visual>
      <origin xyz="0 0 0" rpy="0 0 0" />
      <geometry>
        <!-- <mesh filename="meshes/RLS3_new.obj" scale="1000" /> -->
      </geometry>
      <material name="Orange"/>        
    </visual>
  </link>
  
  <link name="RLS4">
    <inertial>
      <origin xyz="-1.4605 1.8371 3.0882" rpy="0 0 0" />
      <mass value="1.4269E-02" />
      <inertia ixx="1.206E-1" ixy="-3.2785E-2" ixz="2.9892E-2" iyy="8.3598E-2" iyz="2.1738E-2" izz="9.8829E-2" />
    </inertial>
    <visual>
      <origin xyz="0 0 0" rpy="0 0 0" />
      <geometry>
        <!-- <mesh filename="meshes/RLS4_new.obj" scale="1000" /> -->
      </geometry>
      <material name="Orange"/>      
    </visual>
  </link>

  <!--- REAR LEFT LIFT || REAR LEFT LIFT || REAR LEFT LIFT --> 
  <!--- REAR LEFT LIFT || REAR LEFT LIFT || REAR LEFT LIFT --> 
  <!--- REAR LEFT LIFT || REAR LEFT LIFT || REAR LEFT LIFT --> 

  <link name="RLL1">
    <inertial>
      <origin xyz="0.27638 1.552 1.3427E-02" rpy="0 0 0" />
      <mass value="3.4357E-03" />
      <inertia ixx="3.8161E-3" ixy="-3.3823E-4" ixz="-3.5123E-4" iyy="2.1069E-3" iyz="-1.4678E-4" izz="4.1339E-3" />
    </inertial>
    <visual>
      <origin xyz="0 0 0" rpy="0 0 0" />
      <geometry>
        <!-- <mesh filename="meshes/RLL1_new.obj" scale="1000" /> -->
      </geometry>
      <material name="Blue"/>                 
    </visual>
  </link>

  <link name="RLL2">
    <inertial>
      <origin xyz=" 0 0.95907 0" rpy="0 0 0" />
      <mass value="1.6211E-03" />
      <inertia ixx="9.976E-4" ixy="0" ixz="0" iyy="2.561E-3" iyz="0" izz="3.5431E-3" />
    </inertial>
    <visual>
      <origin xyz="0 0 0" rpy="0 0 0" />
      <geometry>
        <!-- <mesh filename="meshes/RLL2_new.obj" scale="1000" /> -->
      </geometry>
      <material name="Blue"/>                  
    </visual>
  </link>

  <link name="RLL3">
    <inertial>
      <origin xyz="-0.11652 -7.2167E-02 -0.5651" rpy="0 0 0" />
      <mass value="4.2308E-03" />
      <inertia ixx="2.4566E-3" ixy="9.4738E-5" ixz="-3.1854E-4" iyy="5.8098E-3" iyz="4.7676E-4" izz="4.4079E-3" />
    </inertial>
    <visual>
      <origin xyz="0 0 0" rpy="0 0 0" />
      <geometry>
        <!-- <mesh filename="meshes/RLL3_new.obj" scale="1000" /> -->
      </geometry>
      <material name="Orange"/>                       
    </visual>
  </link>

  <link name="RLL4">
    <inertial>
      <origin xyz="1.0887 3.2212 -3.5924" rpy="0 0 0" />
      <mass value="3.0948E-02" />
      <inertia ixx="4.79144E-1" ixy="-0.071618" ixz="0.048644" iyy="3.52764E-1" iyz="-0.155393" izz="3.4257E-1" />
    </inertial>
    <visual>
      <origin xyz="0 0 0" rpy="0 0 0" />
      <geometry>
        <!-- <mesh filename="meshes/RLL4_new.obj" scale="1000"/> -->
      </geometry>
      <material name="Orange"/>              
    </visual>
    <collision>
      <origin xyz="0 7.58 -11.35" rpy="0 0 0"/>
      <geometry>
        <sphere radius="0" />
      </geometry>
    </collision>
  </link>

  <!--- REAR LEFT SWING || REAR LEFT SWING || REAR LEFT SWING --> 
  <!--- REAR LEFT SWING || REAR LEFT SWING || REAR LEFT SWING --> 
  <!--- REAR LEFT SWING || REAR LEFT SWING || REAR LEFT SWING --> 

  <link name="FRS1">
    <inertial>
      <origin xyz="0 0 0" rpy="0 0 0" />
      <mass value="8.9854E-04" />
      <inertia ixx="4.0531E-4" ixy="0" ixz="0" iyy="1.8583E-4" iyz="-1.1771E-5" izz="2.281E-4" />
    </inertial>
    <visual>
      <origin xyz="0 0 0" rpy="0 0 0" />
      <geometry>
        <!-- <mesh filename="meshes/FRS1_new.obj" scale="1000" /> -->
      </geometry>
      <material name="Purple"/>        
    </visual>
  </link>

  <link name="FRS2">
    <inertial>
      <origin xyz="0 -3.8176 1.3953" rpy="0 0 0" />
      <mass value="7.2648E-03" />
      <inertia ixx="3.894E-2" ixy="0" ixz="0" iyy="8.899E-3" iyz="-9.1382E-3" izz="3.0111E-2" />
    </inertial>
    <visual>
      <origin xyz="0 0 0" rpy="0 0 0" />
      <geometry>
        <!-- <mesh filename="meshes/FRS2_new.obj" scale="1000" /> -->
      </geometry>
      <material name="Purple"/>        
    </visual>
  </link>

  <link name="FRS3">
    <inertial>
      <origin xyz="0.70289 -8.6332E-02 0.10242" rpy="0 0 0" />
      <mass value="3.889E-03" />
      <inertia ixx="2.6158E-3" ixy="-5.7753E-4" ixz="-3.2642E-4" iyy="4.7809E-3" iyz="-8.2188E-5" izz="3.1897E-3" />
    </inertial>
    <visual>
      <origin xyz="0 0 0" rpy="0 0 0" />
      <geometry>
        <!-- <mesh filename="meshes/FRS3_new.obj" scale="1000" /> -->
      </geometry>
      <material name="Orange"/>        
    </visual>
  </link>

  <link name="FRS4">
    <inertial>
      <origin xyz="1.4605 -1.8371 3.0882" rpy="0 0 0" />
      <mass value="1.4269E-02" />
      <inertia ixx="1.206E-1" ixy="3.2785E-2" ixz="-2.9892E-2" iyy="8.3598E-2" iyz="2.1738E-2" izz="9.8829E-2" />
    </inertial>
    <visual>
      <origin xyz="0 0 0" rpy="0 0 0" />
      <geometry>
        <!-- <mesh filename="meshes/FRS4_new.obj" scale="1000" /> -->
      </geometry>
      <material name="Orange"/>      
    </visual>
  </link>

  <!--- REAR LEFT LIFT || REAR LEFT LIFT || REAR LEFT LIFT --> 
  <!--- REAR LEFT LIFT || REAR LEFT LIFT || REAR LEFT LIFT --> 
  <!--- REAR LEFT LIFT || REAR LEFT LIFT || REAR LEFT LIFT --> 

  <link name="FRL1">
    <inertial>
      <origin xyz="-0.2102 -2.5512 -5.7375E-02" rpy="0 0 0" />
      <mass value="4.5174E-03" />
      <inertia ixx="1.0604E-2" ixy="9.467E-4" ixz="4.1692E-4" iyy="2.5227E-3" iyz="-2.6756E-4" izz="1.0642E-2" />
    </inertial>
    <visual>
      <origin xyz="0 0 0" rpy="0 0 0" />
      <geometry>
        <!-- <mesh filename="meshes/FRL1_new.obj" scale="1000" /> -->
      </geometry>
      <material name="Blue"/>        
    </visual>
  </link>

  <link name="FRL2">
    <inertial>
      <origin xyz="0 -0.95907 0" rpy="0 0 0" />
      <mass value="1.6211E-03" />
      <inertia ixx="9.976E-4" ixy="0" ixz="0" iyy="2.561E-3" iyz="0" izz="3.5431E-3" />
    </inertial>
    <visual>
      <origin xyz="0 0 0" rpy="0 0 0" />
      <geometry>
        <!-- <mesh filename="meshes/FRL2_new.obj" scale="1000" /> -->
      </geometry>
      <material name="Blue"/>        
    </visual>/
  </link>

  <link name="FRL3">
    <inertial>
      <origin xyz="0.11652 7.2167E-02 -0.5651" rpy="0 0 0" />
      <mass value="4.2308E-03" />
      <inertia ixx="2.4566E-3" ixy="-9.4738E-5" ixz="3.1854E-4" iyy="5.8098E-3" iyz="4.7676E-4" izz="4.4079E-3" />
    </inertial>
    <visual>
      <origin xyz="0 0 0" rpy="0 0 0" />
      <geometry>
        <!-- <mesh filename="meshes/FRL3_new.obj" scale="1000" /> -->
      </geometry>
      <material name="Orange"/>        
    </visual>
  </link>  

  <link name="FRL4">
    <inertial>
      <origin xyz="-1.0887 -3.2212 -3.5924" rpy="0 0 0" />
      <mass value="3.0948E-02" />
      <inertia ixx="0.453879" ixy="0.072379" ixz="-0.038860" iyy="0.325606" iyz="0.144657" izz="0.344463" />
    </inertial>
    <visual>
      <origin xyz="0 0 0" rpy="0 0 0" />
      <geometry>
        <!-- <mesh filename="meshes/FRL4_new.obj" scale="1000"/> -->
      </geometry>
      <material name="Orange"/>        
    </visual>
    <collision>
      <origin xyz="0 -7.58 -11.35" rpy="0 0 0"/>
      <geometry>
        <sphere radius="0" />
      </geometry>
    </collision>
  </link>

  <!--- REAR RIGHT SWING || REAR RIGHT SWING || REAR RIGHT SWING --> 
  <!--- REAR RIGHT SWING || REAR RIGHT SWING || REAR RIGHT SWING --> 
  <!--- REAR RIGHT SWING || REAR RIGHT SWING || REAR RIGHT SWING --> 

  <link name="RRS1">
    <inertial>
      <origin xyz="0 0 0" rpy="0 0 0" />
      <mass value="8.9854E-04" />
      <inertia ixx="4.0531E-4" ixy="0" ixz="0" iyy="1.8583E-4" iyz="-1.1771E-5" izz="2.281E-4" />
    </inertial>
    <visual>
      <origin xyz="0 0 0" rpy="0 0 0" />
      <geometry>
        <!-- <mesh filename="meshes/RRS1_new.obj" scale="1000" /> -->
      </geometry>
      <material name="Purple"/>        
    </visual>
  </link>

  <link name="RRS2">
    <inertial>
      <origin xyz="0 -3.8176 1.3953" rpy="0 0 0" />
      <mass value="7.2648E-03" />
      <inertia ixx="3.894E-2" ixy="0" ixz="0" iyy="8.899E-3" iyz="-9.1382E-3" izz="3.0111E-2" />
    </inertial>
    <visual>
      <origin xyz="0 0 0" rpy="0 0 0" />
      <geometry>
        <!-- <mesh filename="meshes/RRS2_new.obj" scale="1000" /> -->
      </geometry>
      <material name="Purple"/>        
    </visual>
  </link>

  <link name="RRS3">
    <inertial>
      <origin xyz="-0.70289 8.6332E-02 0.10242" rpy="0 0 0" />
      <mass value="3.889E-03" />
      <inertia ixx="2.6158E-3" ixy="5.7753E-4" ixz="3.2642E-4" iyy="4.7809E-3" iyz="-8.2188E-5" izz="3.1897E-3" />
    </inertial>
    <visual>
      <origin xyz="0 0 0" rpy="0 0 0" />
      <geometry>
        <!-- <mesh filename="meshes/RRS3_new.obj" scale="1000" /> -->
      </geometry>
      <material name="Orange"/>        
    </visual>
  </link>

  <link name="RRS4">
    <inertial>
      <origin xyz="-1.4605 -1.8371 3.0882" rpy="0 0 0" />
      <mass value="1.4269E-02" />
      <inertia ixx="1.206E-1" ixy="-3.2785E-2" ixz="2.9892E-2" iyy="8.3598E-2"   iyz="2.1738E-2" izz="9.8829E-2" />
    </inertial>
    <visual>
      <origin xyz="0 0 0" rpy="0 0 0" />
      <geometry>
        <!-- <mesh filename="meshes/RRS4_new.obj" scale="1000" /> -->
      </geometry>
      <material name="Orange"/>        
    </visual>
  </link>

  <!--- REAR RIGHT LIFT || REAR RIGHT LIFT || REAR RIGHT LIFT --> 
  <!--- REAR RIGHT LIFT || REAR RIGHT LIFT || REAR RIGHT LIFT --> 
  <!--- REAR RIGHT LIFT || REAR RIGHT LIFT || REAR RIGHT LIFT --> 

  <link name="RRL1">
    <inertial>
      <origin xyz="0.27638 -1.552 1.3427E-02" rpy="0 0 0" />
      <mass value="3.4357E-03" />
      <inertia ixx="3.8161E-3" ixy="-3.3823E-4" ixz="-3.5123E-4" iyy="2.1069E-3" iyz="-1.4678E-4" izz="4.1339E-3" />
    </inertial>
    <visual>
      <origin xyz="0 0 0" rpy="0 0 0" />
      <geometry>
        <!-- <mesh filename="meshes/RRL1_new.obj" scale="1000" /> -->
      </geometry>
      <material name="Blue"/>        
    </visual>
  </link>

  <link name="RRL2">
    <inertial>
      <origin xyz=" 0 -0.95907 0" rpy="0 0 0" />
      <mass value="1.6211E-03" />
      <inertia ixx="9.976E-4" ixy="0" ixz="0" iyy="2.561E-3" iyz="0" izz="3.5431E-3" />
    </inertial>
    <visual>
      <origin xyz="0 0 0" rpy="0 0 0" />
      <geometry>
        <!-- <mesh filename="meshes/RRL2_new.obj" scale="1000" /> -->
      </geometry>
      <material name="Blue"/>        
    </visual>
  </link>

  <link name="RRL3">
    <inertial>
      <origin xyz="-0.11652 7.2167E-02 -0.5651" rpy="0 0 0" />
      <mass value="4.2308E-03" />
      <inertia ixx="2.4566E-3" ixy="9.4738E-5" ixz="-3.1854E-4" iyy="5.8098E-3" iyz="4.7676E-4" izz="4.4079E-3" />
    </inertial>
    <visual>
      <origin xyz="0 0 0" rpy="0 0 0" />
      <geometry>
        <!-- <mesh filename="meshes/RRL3_new.obj" scale="1000" /> -->
      </geometry>
      <material name="Orange"/>
    </visual>
  </link>

  <link name="RRL4">
    <inertial>
      <origin xyz="1.0887 -3.2212 -3.5924" rpy="0 0 0" />
      <mass value="3.0948E-02" />
      <inertia ixx="4.79144E-1" ixy="0.071618" ixz=" 0.048644" iyy="3.52764E-1" iyz="0.155393" izz="3.42572E-1" />
    </inertial>
    <visual>
      <origin xyz="0 0 0" rpy="0 0 0" />
      <geometry>
        <!-- <mesh filename="meshes/RRL4_new.obj" scale="1000"/> -->
      </geometry>
      <material name="Orange"/>        
    </visual>
    <collision>
      <origin xyz="0 -7.58 -11.35" rpy="0 0 0"/>
      <geometry>
        <sphere radius="0" />
      </geometry>
    </collision>
  </link>  

  <!-- JOINTS ||| JOINTS ||| JOINTS ||| JOINTS ||| JOINTS |||-->
  <!-- JOINTS ||| JOINTS ||| JOINTS ||| JOINTS ||| JOINTS |||-->
  <!-- JOINTS ||| JOINTS ||| JOINTS ||| JOINTS ||| JOINTS |||-->
  <!-- JOINTS ||| JOINTS ||| JOINTS ||| JOINTS ||| JOINTS |||-->
  <!-- JOINTS ||| JOINTS ||| JOINTS ||| JOINTS ||| JOINTS |||-->
  <!-- JOINTS ||| JOINTS ||| JOINTS ||| JOINTS ||| JOINTS |||-->
  <!-- JOINTS ||| JOINTS ||| JOINTS ||| JOINTS ||| JOINTS |||-->
  <!-- JOINTS ||| JOINTS ||| JOINTS ||| JOINTS ||| JOINTS |||-->
  <!-- JOINTS ||| JOINTS ||| JOINTS ||| JOINTS ||| JOINTS |||-->
  <!-- JOINTS ||| JOINTS ||| JOINTS ||| JOINTS ||| JOINTS |||-->


  <!--- FRONT LEFT SWING || FRONT LEFT SWING || FRONT LEFT SWING --> 
  <!--- FRONT LEFT SWING || FRONT LEFT SWING || FRONT LEFT SWING --> 
  <!--- FRONT LEFT SWING || FRONT LEFT SWING || FRONT LEFT SWING --> 


  <joint name="FLqsact" type="prismatic">
    <origin xyz="13.284659815390 1.456684126580 -0.478250429210" rpy="0 0 0" />
    <parent link="Chassis" />
    <child link="FLS1" />
    <axis xyz="0 1 0" />
    <limit lower="-0.3" upper="0.3" />
    <dynamics damping="0.01" />
  </joint>

  <joint name="FLqs1" type="revolute">
    <origin xyz="0 0.77116874934 0.12648211488" rpy="0 0 0" />
    <parent link="FLS1" />
    <child link="FLS2" />
    <axis xyz="0 0 1" />
    <dynamics damping="2.804E-2" />
  </joint>

  <joint name="FLqs2" type="revolute">
    <origin  xyz="0 7.44214712409 2.06176831433" rpy="0 0 0" />
    <parent link="FLS2" />
    <child link="FLS3" />
    <axis xyz="0 0 1" />
    <dynamics damping="1.657E-2" />
  </joint>

  <joint name="FLqfb1" type="revolute">
    <origin xyz="1.52236486487 0.12 -1.25" rpy="0 0 0" />
    <parent link="FLS3" />
    <child link="FLS4" />
    <axis xyz="1 0 0" />
    <dynamics damping="1.914E-2" />
  </joint> 


  <!--- FRONT LEFT LIFT || FRONT LEFT LIFT || FRONT LEFT LIFT --> 
  <!--- FRONT LEFT LIFT || FRONT LEFT LIFT || FRONT LEFT LIFT --> 
  <!--- FRONT LEFT LIFT || FRONT LEFT LIFT || FRONT LEFT LIFT --> 

  <joint name="FLqlact" type="prismatic">
    <origin xyz="10.504659815390 3.151779821480 -0.501688531240" rpy="0 0 0" />
    <parent link="Chassis" />
    <child link="FLL1" />
    <axis xyz="0 1 0" />
    <limit lower="-0.3" upper="0.3" />
    <dynamics damping="0.01" />
  </joint>

  <joint name="FLql1" type="revolute">
    <origin  xyz="0 4.57322017852 0.38168853124" rpy="0 0 0" />
    <parent link="FLL1" />
    <child link="FLL2" />
    <axis xyz="1 0 0" />
    <dynamics damping="6.366E-2" />
  </joint>

  <joint name="FLql2" type="revolute">
    <origin xyz="0 1.945 0" rpy="0 0 0" />
    <parent link="FLL2" />
    <child link="FLL3" />
    <axis xyz="1 0 0" />
    <dynamics damping="1.657E-2" />
  </joint>  

  <joint name="FLqfb3" type="revolute">
    <origin xyz="2.25 0.12 -1.07" rpy="0 0 0" />
    <parent link="FLL3" />
    <child link="FLL4" />
    <axis xyz="0 0 1" />
    <dynamics damping="1.657E-2" />
  </joint>

  <!--- REAR LEFT SWING || REAR LEFT SWING || REAR LEFT SWING --> 
  <!--- REAR LEFT SWING || REAR LEFT SWING || REAR LEFT SWING --> 
  <!--- REAR LEFT SWING || REAR LEFT SWING || REAR LEFT SWING --> 

  <joint name="RLqsact" type="prismatic">
    <origin xyz="-13.284659815390 1.456684126580 -0.478250429210" rpy="0 0 0" />
    <parent link="Chassis" />
    <child link="RLS1" />
    <axis xyz="0 1 0" />
    <limit lower="-0.3" upper="0.3" />
    <dynamics damping="0.01" />
  </joint>

  <joint name="RLqs1" type="revolute">
    <origin xyz="0 0.77116874934 0.12648211488" rpy="0 0 0" />
    <parent link="RLS1" />
    <child link="RLS2" />
    <axis xyz="0 0 1" />
    <dynamics damping="2.804E-2" />
  </joint>

  <joint name="RLqs2" type="revolute">
    <origin xyz="0 7.44214712409 2.06176831433" rpy="0 0 0" />
    <parent link="RLS2" />
    <child link="RLS3" />
    <axis xyz="0 0 1" />
    <dynamics damping="1.657E-2" />
  </joint>

  <joint name="RLqfb1" type="revolute">
    <origin xyz="-1.52236486487 0.12 -1.25" rpy="0 0 0" />
    <parent link="RLS3" />
    <child link="RLS4" />
    <axis xyz="1 0 0" />
    <dynamics damping="1.914E-2" />
  </joint> 

  <!--- REAR LEFT LIFT || REAR LEFT LIFT || REAR LEFT LIFT --> 
  <!--- REAR LEFT LIFT || REAR LEFT LIFT || REAR LEFT LIFT --> 
  <!--- REAR LEFT LIFT || REAR LEFT LIFT || REAR LEFT LIFT --> 

  <joint name="RLqlact" type="prismatic">
    <origin xyz="-10.504659815390 4.791779821480 -0.501688531240" rpy="0 0 0" />
    <parent link="Chassis" />
    <child link="RLL1" />
    <axis xyz="0 1 0" />
    <limit lower="-0.3" upper="0.3" />
    <dynamics damping="0.01" />
  </joint>

  <joint name="RLql1" type="revolute">
    <origin xyz="0 2.93322017852 0.38168853124" rpy="0 0 0" />
    <parent link="RLL1" />
    <child link="RLL2" />
    <axis xyz="1 0 0" />
    <dynamics damping="6.366E-2" />
  </joint>

  <joint name="RLql2"
    type="revolute">
    <origin xyz="0 1.945 0" rpy="0 0 0" />
    <parent link="RLL2" />
    <child link="RLL3" />
    <axis  xyz="1 0 0" />
    <dynamics damping="1.657E-2" />
  </joint>

  <joint name="RLqfb3" type="revolute">
    <origin xyz="-2.25 0.12 -1.07" rpy="0 0 0" />
    <parent link="RLL3" />
    <child link="RLL4" />
    <axis xyz="0 0 1" />
    <dynamics damping="1.657E-2" />
  </joint>

  <!--- FRONT RIGHT SWING || FRONT RIGHT SWING || FRONT RIGHT SWING --> 
  <!--- FRONT RIGHT SWING || FRONT RIGHT SWING || FRONT RIGHT SWING --> 
  <!--- FRONT RIGHT SWING || FRONT RIGHT SWING || FRONT RIGHT SWING --> 

  <joint name="FRqsact" type="prismatic">
    <origin xyz="13.284659815390 -1.456684126580 -0.478250429210" rpy="0 0 0" />
    <parent link="Chassis" />
    <child link="FRS1" />
    <axis xyz="0 1 0" />
    <limit lower="-0.3" upper="0.3" />
    <dynamics damping="0.01" />
  </joint>

  <joint name="FRqs1" type="revolute">
    <origin xyz="0 -0.77116874934 0.12648211488" rpy="0 0 0" />
    <parent link="FRS1" />
    <child link="FRS2" />
    <axis xyz="0 0 1" />
    <dynamics damping="2.804E-2" />
  </joint>

  <joint name="FRqs2" type="revolute">
    <origin xyz="0 -7.44214712409 2.06176831433" rpy="0 0 0" />
    <parent link="FRS2" />
    <child link="FRS3" />
    <axis xyz="0 0 1" />
    <dynamics damping="1.657E-2" />
  </joint>

  <joint name="FRqfb1" type="revolute">
    <origin xyz="1.52236486487 -0.12 -1.25" rpy="0 0 0" />
    <parent link="FRS3" />
    <child link="FRS4" />
    <axis xyz="1 0 0" />
    <dynamics damping="1.914E-2" />
  </joint>

  <!--- FRONT RIGHT LIFT || FRONT RIGHT LIFT || FRONT RIGHT LIFT --> 
  <!--- FRONT RIGHT LIFT || FRONT RIGHT LIFT || FRONT RIGHT LIFT --> 
  <!--- FRONT RIGHT LIFT || FRONT RIGHT LIFT || FRONT RIGHT LIFT --> 

  <joint name="FRqlact" type="prismatic">
    <origin xyz="10.504659815390 -3.151779821480 -0.501688531240" rpy="0 0 0" />
    <parent link="Chassis" />
    <child link="FRL1" />
    <axis xyz="0 1 0" />
    <limit lower="-0.3" upper="0.3" />
    <dynamics damping="0.01" />
  </joint>

  <joint name="FRql1" type="revolute">
    <origin xyz="0 -4.57322017852 0.38168853124" rpy="0 0 0" />
    <parent link="FRL1" />
    <child link="FRL2" />
    <axis xyz="1 0 0" />
    <dynamics damping="6.366E-2" />
  </joint>

  <joint name="FRql2" type="revolute">
    <origin xyz="0 -1.945 0" rpy="0 0 0" />
    <parent link="FRL2" />
    <child link="FRL3" />
    <axis xyz="1 0 0" />
    <dynamics damping="1.657E-2" />
  </joint>

  <joint name="FRqfb3" type="revolute">
    <origin xyz="2.25 -0.12 -1.07" rpy="0 0 0" />
    <parent link="FRL3" />
    <child link="FRL4" />
    <axis xyz="0 0 1" />
    <dynamics damping="1.657E-2" />
  </joint> 

  <!--- REAR RIGHT SWING || REAR RIGHT SWING || REAR RIGHT SWING --> 
  <!--- REAR RIGHT SWING || REAR RIGHT SWING || REAR RIGHT SWING --> 
  <!--- REAR RIGHT SWING || REAR RIGHT SWING || REAR RIGHT SWING -->

  <joint name="RRqsact" type="prismatic">
    <origin xyz="-13.284659815390 -1.456684126580 -0.478250429210" rpy="0 0 0" />
    <parent link="Chassis" />
    <child link="RRS1" />
    <axis xyz="0 1 0" />
    <limit lower="-0.3" upper="0.3" />
    <dynamics damping="0.01" />
  </joint>

  <joint name="RRqs1" type="revolute">
    <origin xyz="0 -0.77116874934 0.12648211488" rpy="0 0 0" />
    <parent link="RRS1" />
    <child link="RRS2" />
    <axis xyz="0 0 1" />
    <dynamics damping="2.804E-2" />
  </joint>

  <joint name="RRqs2" type="revolute">
    <origin xyz="0 -7.44214712409 2.06176831433" rpy="0 0 0" />
    <parent link="RRS2" />
    <child link="RRS3" />
    <axis xyz="0 0 1" />
    <dynamics damping="1.657E-2" />
  </joint>

  <joint name="RRqfb1" type="revolute">
    <origin xyz="-1.52236486487 -0.12 -1.25" rpy="0 0 0" />
    <parent link="RRS3" />
    <child link="RRS4" />
    <axis xyz="1 0 0" />    
    <dynamics damping="1.914E-2" />
  </joint> 

  <!--- REAR RIGHT SWING || REAR RIGHT SWING || REAR RIGHT SWING --> 
  <!--- REAR RIGHT SWING || REAR RIGHT SWING || REAR RIGHT SWING --> 
  <!--- REAR RIGHT SWING || REAR RIGHT SWING || REAR RIGHT SWING -->

  <joint name="RRqlact" type="prismatic">
    <origin xyz="-10.504659815390 -4.791779821480 -0.501688531240" rpy="0 0 0" />
    <parent link="Chassis" />
    <child link="RRL1" />
    <axis xyz="0 1 0" />
    <limit lower="-0.3" upper="0.3" />
    <dynamics damping="0.01" />
  </joint>

  <joint name="RRql1" type="revolute">
    <origin xyz="0 -2.93322017852 0.38168853124" rpy="0 0 0" />
    <parent link="RRL1" />
    <child link="RRL2" />
    <axis xyz="1 0 0" />
    <dynamics damping="6.366E-2" />
  </joint>

  <joint name="RRql2" type="revolute">
    <origin xyz="0 -1.945 0" rpy="0 0 0" />
    <parent link="RRL2" />
    <child link="RRL3" />
    <axis xyz="1 0 0" />
    <dynamics damping="1.657E-2" />
  </joint>

  <joint name="RRqfb3" type="revolute">
    <origin xyz="-2.25 -0.12 -1.07" rpy="0 0 0" />
    <parent link="RRL3" />
    <child link="RRL4" />
    <axis xyz="0 0 1" />
    <dynamics damping="1.657E-2" />
  </joint> 

  <!-- LOOP CONST ||| LOOP CONST ||| LOOP CONST ||| LOOP CONST -->
  <!-- LOOP CONST ||| LOOP CONST ||| LOOP CONST ||| LOOP CONST -->
  <!-- LOOP CONST ||| LOOP CONST ||| LOOP CONST ||| LOOP CONST -->
  <!-- LOOP CONST ||| LOOP CONST ||| LOOP CONST ||| LOOP CONST -->
  <!-- LOOP CONST ||| LOOP CONST ||| LOOP CONST ||| LOOP CONST -->
  <!-- LOOP CONST ||| LOOP CONST ||| LOOP CONST ||| LOOP CONST -->
  <!-- LOOP CONST ||| LOOP CONST ||| LOOP CONST ||| LOOP CONST -->
  <!-- LOOP CONST ||| LOOP CONST ||| LOOP CONST ||| LOOP CONST -->
  <!-- LOOP CONST ||| LOOP CONST ||| LOOP CONST ||| LOOP CONST -->
  <!-- LOOP CONST ||| LOOP CONST ||| LOOP CONST ||| LOOP CONST -->
  <!-- LOOP CONST ||| LOOP CONST ||| LOOP CONST ||| LOOP CONST -->
  <!-- LOOP CONST ||| LOOP CONST ||| LOOP CONST ||| LOOP CONST -->

  <loop_joint name="FLqs3" type="continuous">
    <axis xyz="0 0 1"/>
    <link1 link="Chassis" rpy="0 0 0" xyz="12.754659815390 9.79 1.71" />
    <link2 link="FLS3" rpy="0 0 0" xyz= "-0.53 0.12 0.0" />
  </loop_joint>

  <loop_joint name="FLql3" type="continuous">
    <axis xyz="1 0 0" />
    <link1 link="Chassis" rpy="0 0 0" xyz="10.504659815390 9.79 0.46"/>
    <link2 link="FLL3" rpy="0 0 0" xyz= "0.0 0.12 0.58"/>
  </loop_joint>

  <loop_joint  name="FLqfb2"  type="continuous">
    <axis xyz="0 1 0" />
    <link1 link="FLS4" rpy="0 0 0" xyz="-2.05236472111 5.98079552649 0.0"/> 
    <link2 link="FLL4" rpy="0 0 0" xyz="0.0 5.98079552649 1.64999985615" />
  </loop_joint> 

  <loop_joint name="RLqs3" type="continuous">
    <axis xyz="0 0 1" />
    <link1 link="Chassis" rpy="0 0 0" xyz="-12.754659815390 9.79 1.71" />
    <link2 link="RLS3" rpy="0 0 0" xyz= "0.53 0.12 0.0" />
  </loop_joint>

  <loop_joint name="RLql3" type="continuous">
    <axis xyz="1 0 0" />
    <link1 link="Chassis" rpy="0 0 0" xyz="-10.504659815390  9.79 0.46"/>
    <link2 link="RLL3" rpy="0 0 0" xyz= "0.0 0.12 0.58"/>
  </loop_joint>

  <loop_joint  name="RLqfb2"  type="continuous">
    <axis xyz="0 1 0" />
    <link1 link="RLS4" rpy="0 0 0" xyz="2.05236472111 5.98079552649 0.0"/> 
    <link2 link="RLL4" rpy="0 0 0" xyz="0.0 5.98079552649 1.64999985615"/>
  </loop_joint>

  <loop_joint name="FRqs3" type="continuous">
    <axis xyz="0 0 1" />
    <link1 link="Chassis" rpy="0 0 0" xyz="12.754659815390 -9.79 1.71" />
    <link2 link="FRS3" rpy="0 0 0" xyz= "-0.53 -0.12 0.0" />
  </loop_joint>

  <loop_joint name="FRql3" type="continuous">
    <axis xyz="1 0 0" />
    <link1 link="Chassis" rpy="0 0 0" xyz="10.504659815390 -9.79 0.46"/>
    <link2 link="FRL3"  rpy="0 0 0" xyz= "0.0 -0.12 0.58"/>
  </loop_joint>

  <loop_joint  name="FRqfb2"  type="continuous">
    <axis xyz="0 1 0" />
    <link1 link="FRS4" rpy="0 0 0" xyz="-2.05236472111 -5.98079552649 0.0"/> 
    <link2 link="FRL4" rpy="0 0 0" xyz="0.0 -5.98079552649 1.64999985615" />
  </loop_joint>

  <loop_joint name="RRqs3" type="continuous">
    <axis xyz="0 0 1" />
    <link1 link="Chassis" rpy="0 0 0" xyz="-12.754659815390 -9.79 1.71" />
    <link2 link="RRS3" rpy="0 0 0" xyz= "0.53 -0.12 0.0" />
  </loop_joint>

  <loop_joint name="RRql3" type="continuous">
    <axis xyz="1 0 0" />
    <link1 link="Chassis" rpy="0 0 0" xyz="-10.504659815390 -9.79 0.46"/>
    <link2 link="RRL3"  rpy="0 0 0" xyz= "0.0 -0.12 0.58"/>
  </loop_joint>

  <loop_joint  name="RRqfb2"  type="continuous">
    <axis xyz="0 1 0" />
    <link1 link="RRS4" rpy="0 0 0" xyz="2.05236472111 -5.98079552649 0.0"/> 
    <link2 link="RRL4" rpy="0 0 0" xyz="0.0 -5.98079552649 1.64999985615" />
  </loop_joint>  


  <!-- SPRINGS ||| SPRINGS ||| SPRINGS ||| SPRINGS -->
  <!-- SPRINGS ||| SPRINGS ||| SPRINGS ||| SPRINGS -->
  <!-- SPRINGS ||| SPRINGS ||| SPRINGS ||| SPRINGS -->
  <!-- SPRINGS ||| SPRINGS ||| SPRINGS ||| SPRINGS -->
  <!-- SPRINGS ||| SPRINGS ||| SPRINGS ||| SPRINGS -->
  <!-- SPRINGS ||| SPRINGS ||| SPRINGS ||| SPRINGS -->
  <!-- SPRINGS ||| SPRINGS ||| SPRINGS ||| SPRINGS -->
  <!-- SPRINGS ||| SPRINGS ||| SPRINGS ||| SPRINGS -->
  <!-- SPRINGS ||| SPRINGS ||| SPRINGS ||| SPRINGS -->
  <!-- SPRINGS ||| SPRINGS ||| SPRINGS ||| SPRINGS -->
  <!-- SPRINGS ||| SPRINGS ||| SPRINGS ||| SPRINGS -->
  <!-- SPRINGS ||| SPRINGS ||| SPRINGS ||| SPRINGS -->

  <force_element name="FL_ks1">
    <torsional_spring stiffness="9.2E-2" rest_angle="0">
      <joint name="FLqs1" />
    </torsional_spring>
  </force_element>

  <force_element name="FL_ks2">
    <torsional_spring stiffness="3.4E-2" rest_angle="0">
      <joint name="FLqs2" />
    </torsional_spring>
  </force_element>

  <force_element name="RL_ks1">
    <torsional_spring stiffness="9.2E-2" rest_angle="0">
      <joint name="RLqs1" />
    </torsional_spring>
  </force_element>

  <force_element name="RL_ks2">
    <torsional_spring stiffness="3.4E-2" rest_angle="0">
      <joint name="RLqs2" />
    </torsional_spring>
  </force_element>

  <force_element name="FR_ks1">
    <torsional_spring stiffness="9.2E-2" rest_angle="0">
      <joint name="FRqs1" />
    </torsional_spring>
  </force_element>

  <force_element name="FR_ks2">
    <torsional_spring stiffness="3.4E-2" rest_angle="0">
      <joint name="FRqs2" />
    </torsional_spring>
  </force_element>

  <force_element name="RR_ks1">
    <torsional_spring stiffness="9.2E-2" rest_angle="0">
      <joint name="RRqs1" />
    </torsional_spring>
  </force_element>

  <force_element name="RR_ks2">
    <torsional_spring stiffness="3.4E-2" rest_angle="0">
      <joint name="RRqs2" />
    </torsional_spring>
  </force_element>


  <!-- LIFT SPRINGS ||| LIFT SPRINGS ||| LIFT SPRINGS ||| LIFT SPRINGS -->
  <!-- LIFT SPRINGS ||| LIFT SPRINGS ||| LIFT SPRINGS ||| LIFT SPRINGS -->
  <!-- LIFT SPRINGS ||| LIFT SPRINGS ||| LIFT SPRINGS ||| LIFT SPRINGS -->

  <force_element name="FL_kl1">
    <torsional_spring stiffness="2E-1" rest_angle="0">
      <joint name="FLql1" />
    </torsional_spring>
  </force_element>

  <force_element name="FL_kl2">
    <torsional_spring stiffness="3.4E-2" rest_angle="0">
      <joint name="FLql2" />
    </torsional_spring>
  </force_element>

  <force_element name="RL_kl1">
    <torsional_spring stiffness="2E-1" rest_angle="0">
      <joint name="RLql1" />
    </torsional_spring>
  </force_element>

  <force_element name="RL_kl2">
    <torsional_spring stiffness="3.4E-2" rest_angle="0">
      <joint name="RLql2" />
    </torsional_spring>
  </force_element>

  <force_element name="FR_kl1">
    <torsional_spring stiffness="2E-1" rest_angle="0">
      <joint name="FRql1" />
    </torsional_spring>
  </force_element>

  <force_element name="FR_kl2">
    <torsional_spring stiffness="3.4E-2" rest_angle="0">
      <joint name="FRql2" />
    </torsional_spring>
  </force_element>

  <force_element name="RR_kl1">
    <torsional_spring stiffness="2E-1" rest_angle="0">
      <joint name="RRql1" />
    </torsional_spring>
  </force_element>

  <force_element name="RR_kl2">
    <torsional_spring stiffness="3.4E-2" rest_angle="0">
      <joint name="RRql2" />
    </torsional_spring>
  </force_element>  

  <!-- SFB SPRINGS ||| SFB SPRINGS ||| SFB SPRINGS ||| SFB SPRINGS -->
  <!-- SFB SPRINGS ||| SFB SPRINGS ||| SFB SPRINGS ||| SFB SPRINGS -->
  <!-- SFB SPRINGS ||| SFB SPRINGS ||| SFB SPRINGS ||| SFB SPRINGS -->

  <force_element name="FL_kfb1">
    <torsional_spring stiffness="6E-2" rest_angle="0">
      <joint name="FLqfb1" />
    </torsional_spring>
  </force_element>

  <force_element name="FL_kfb3">
    <torsional_spring stiffness="3.4E-2" rest_angle="0">
      <joint name="FLqfb3" />
    </torsional_spring>
  </force_element>

  <force_element name="RL_kfb1">
    <torsional_spring stiffness="6E-2" rest_angle="0">
      <joint name="RLqfb1" />
    </torsional_spring>
  </force_element>

  <force_element name="RL_kfb3">
    <torsional_spring stiffness="3.4E-2" rest_angle="0">
      <joint name="RLqfb3" />
    </torsional_spring>
  </force_element>

  <force_element name="FR_kfb1">
    <torsional_spring stiffness="6E-2" rest_angle="0">
      <joint name="FRqfb1" />
    </torsional_spring>
  </force_element>

  <force_element name="FR_kfb3">
    <torsional_spring stiffness="3.4E-2" rest_angle="0">
      <joint name="FRqfb3" />
    </torsional_spring>
  </force_element>

  <force_element name="RR_kfb1">
    <torsional_spring stiffness="6E-2" rest_angle="0">
      <joint name="RRqfb1" />
    </torsional_spring>
  </force_element>

  <force_element name="RR_kfb3">
    <torsional_spring stiffness="3.4E-2" rest_angle="0">
      <joint name="RRqfb3" />
    </torsional_spring>
  </force_element>

  <!-- ACT SPRINGS ||| ACT SPRINGS ||| ACT SPRINGS ||| ACT SPRINGS -->
  <!-- ACT SPRINGS ||| ACT SPRINGS ||| ACT SPRINGS ||| ACT SPRINGS -->
  <!-- ACT SPRINGS ||| ACT SPRINGS ||| ACT SPRINGS ||| ACT SPRINGS -->

  <force_element name="FL_ksact">
    <prismatic_spring stiffness="1.1556" rest_length="0">
      <joint name="FLqsact" />
    </prismatic_spring>
  </force_element>

  <force_element name="FL_klact">
    <prismatic_spring stiffness="1.1556" rest_length="0">
      <joint name="FLqlact" />
    </prismatic_spring>
  </force_element>

  <force_element name="RL_ksact">
    <prismatic_spring stiffness="1.1556" rest_length="0">
      <joint name="RLqsact" />
    </prismatic_spring>
  </force_element>

  <force_element name="RL_klact">
    <prismatic_spring stiffness="1.1556" rest_length="0">
      <joint name="RLqlact" />
    </prismatic_spring>
  </force_element>

  <force_element name="FR_ksact">
    <prismatic_spring stiffness="1.1556" rest_length="0">
      <joint name="FRqsact" />
    </prismatic_spring>
  </force_element>

  <force_element name="FR_klact">
   <prismatic_spring stiffness="1.1556" rest_length="0">
    <joint name="FRqlact" />
  </prismatic_spring>
</force_element>

<force_element name="RR_ksact">
  <prismatic_spring stiffness="1.1556" rest_length="0">
    <joint name="RRqsact" />
  </prismatic_spring>
</force_element>

<force_element name="RR_klact">
  <prismatic_spring stiffness="1.1556" rest_length="0">
    <joint name="RRqlact" />
  </prismatic_spring>
</force_element>

<!-- MOTORS ||| MOTORS ||| MOTORS ||| MOTORS ||| MOTORS |||-->
<!-- MOTORS ||| MOTORS ||| MOTORS ||| MOTORS ||| MOTORS |||-->
<!-- MOTORS ||| MOTORS ||| MOTORS ||| MOTORS ||| MOTORS |||-->
<!-- MOTORS ||| MOTORS ||| MOTORS ||| MOTORS ||| MOTORS |||-->
<!-- MOTORS ||| MOTORS ||| MOTORS ||| MOTORS ||| MOTORS |||-->
<!-- MOTORS ||| MOTORS ||| MOTORS ||| MOTORS ||| MOTORS |||-->
<!-- MOTORS ||| MOTORS ||| MOTORS ||| MOTORS ||| MOTORS |||-->
<!-- MOTORS ||| MOTORS ||| MOTORS ||| MOTORS ||| MOTORS |||-->
<!-- MOTORS ||| MOTORS ||| MOTORS ||| MOTORS ||| MOTORS |||-->
<!-- MOTORS ||| MOTORS ||| MOTORS ||| MOTORS ||| MOTORS |||-->

<transmission type="SimpleTransmission" name="FLSwing">
  <actuator name="FLsact" />
  <joint name="FLqsact" />
  <mechanicalReduction>1</mechanicalReduction>
</transmission>

<transmission type="SimpleTransmission" name="FLLift">
  <actuator name="FLlact" />
  <joint name="FLqlact" />
  <mechanicalReduction>1</mechanicalReduction>
</transmission>

<transmission type="SimpleTransmission" name="RLSwing">
  <actuator name="RLsact" />
  <joint name="RLqsact" />
  <mechanicalReduction>1</mechanicalReduction>
</transmission>

<transmission type="SimpleTransmission" name="RLLift">
  <actuator name="RLlact" />
  <joint name="RLqlact" />
  <mechanicalReduction>1</mechanicalReduction>
</transmission>

<transmission type="SimpleTransmission" name="FRSwing">
  <actuator name="FRsact" />
  <joint name="FRqsact" />
  <mechanicalReduction>1</mechanicalReduction>
</transmission>

<transmission type="SimpleTransmission" name="FRLift">
  <actuator name="FRlact" />
  <joint name="FRqlact" />
  <mechanicalReduction>1</mechanicalReduction>
</transmission>

<transmission type="SimpleTransmission" name="RRSwing">
  <actuator name="RRsact" />
  <joint name="RRqsact" />
  <mechanicalReduction>1</mechanicalReduction>
</transmission>

<transmission type="SimpleTransmission" name="RRLift">
  <actuator name="RRlact" />
  <joint name="RRqlact" />
  <mechanicalReduction>1</mechanicalReduction>
</transmission> 

</robot>
